<?xml version="1.0" ?>
<!-- =================================================================================== -->
<!-- |    This document was autogenerated by xacro from /home/teleoptemp/repo/avatar_ws/src/avatar_simulation/avatar_robot_description/franka/dual_panda/dual_panda_example.urdf.xacro | -->
<!-- |    EDITING THIS FILE BY HAND IS NOT RECOMMENDED                                 | -->
<!-- =================================================================================== -->
<robot name="avatar">
  <!-- box shaped table as base for the 2 Pandas -->
  <!-- prop in meters -->
  <link name="base">
    <!-- Box edge visualization -->
    <!-- Top face -->
    <visual>
      <origin rpy="0 0 0" xyz="0.26749999999999996 0 -0.245"/>
      <geometry>
        <box size="0.03 0.51 0.03"/>
      </geometry>
      <material name="Mat Black 1">
        <color rgba="0.1 0.1 0.1 1.0"/>
      </material>
    </visual>
    <visual>
      <origin rpy="0 0 0" xyz="0.26749999999999996 0 0.245"/>
      <geometry>
        <box size="0.03 0.51 0.03"/>
      </geometry>
      <material name="Mat Black 1">
        <color rgba="0.1 0.1 0.1 1.0"/>
      </material>
    </visual>
    <visual>
      <origin rpy="0 0 0" xyz="0.26749999999999996 -0.24 0"/>
      <geometry>
        <box size="0.03 0.03 0.52"/>
      </geometry>
      <material name="Mat Black 1">
        <color rgba="0.1 0.1 0.1 1.0"/>
      </material>
    </visual>
    <visual>
      <origin rpy="0 0 0" xyz="0.26749999999999996 0.24 0"/>
      <geometry>
        <box size="0.03 0.03 0.52"/>
      </geometry>
      <material name="Mat Black 1">
        <color rgba="0.1 0.1 0.1 1.0"/>
      </material>
    </visual>
    <!-- Bottom face -->
    <visual>
      <origin rpy="0 0 0" xyz="-0.26749999999999996 0 -0.245"/>
      <geometry>
        <box size="0.03 0.51 0.03"/>
      </geometry>
      <material name="Mat Black 1">
        <color rgba="0.1 0.1 0.1 1.0"/>
      </material>
    </visual>
    <visual>
      <origin rpy="0 0 0" xyz="-0.26749999999999996 0 0.245"/>
      <geometry>
        <box size="0.03 0.51 0.03"/>
      </geometry>
      <material name="Mat Black 1">
        <color rgba="0.1 0.1 0.1 1.0"/>
      </material>
    </visual>
    <visual>
      <origin rpy="0 0 0" xyz="-0.26749999999999996 -0.24 0"/>
      <geometry>
        <box size="0.03 0.03 0.52"/>
      </geometry>
      <material name="Mat Black 1">
        <color rgba="0.1 0.1 0.1 1.0"/>
      </material>
    </visual>
    <visual>
      <origin rpy="0 0 0" xyz="-0.26749999999999996 0.24 0"/>
      <geometry>
        <box size="0.03 0.03 0.52"/>
      </geometry>
      <material name="Mat Black 1">
        <color rgba="0.1 0.1 0.1 1.0"/>
      </material>
    </visual>
    <!-- Side faces -->
    <!-- right -->
    <visual>
      <origin rpy="0 0 0" xyz="0 0.24 -0.245"/>
      <geometry>
        <box size="0.565 0.03 0.03"/>
      </geometry>
      <material name="Mat Black 1">
        <color rgba="0.1 0.1 0.1 1.0"/>
      </material>
    </visual>
    <visual>
      <origin rpy="0 0 0" xyz="0 0.24 0.245"/>
      <geometry>
        <box size="0.565 0.03 0.03"/>
      </geometry>
      <material name="Mat Black 1">
        <color rgba="0.1 0.1 0.1 1.0"/>
      </material>
    </visual>
    <visual>
      <origin rpy="0 0 0" xyz="-0.26749999999999996 0.24 0"/>
      <geometry>
        <box size="0.03 0.03 0.52"/>
      </geometry>
      <material name="Mat Black 1">
        <color rgba="0.1 0.1 0.1 1.0"/>
      </material>
    </visual>
    <visual>
      <origin rpy="0 0 0" xyz="0.26749999999999996 0.24 0"/>
      <geometry>
        <box size="0.03 0.03 0.52"/>
      </geometry>
      <material name="Mat Black 1">
        <color rgba="0.1 0.1 0.1 1.0"/>
      </material>
    </visual>
    <!-- left -->
    <visual>
      <origin rpy="0 0 0" xyz="0 -0.24 -0.245"/>
      <geometry>
        <box size="0.565 0.03 0.03"/>
      </geometry>
      <material name="Mat Black 1">
        <color rgba="0.1 0.1 0.1 1.0"/>
      </material>
    </visual>
    <visual>
      <origin rpy="0 0 0" xyz="0 -0.24 0.245"/>
      <geometry>
        <box size="0.565 0.03 0.03"/>
      </geometry>
      <material name="Mat Black 1">
        <color rgba="0.1 0.1 0.1 1.0"/>
      </material>
    </visual>
    <visual>
      <origin rpy="0 0 0" xyz="-0.26749999999999996 -0.24 0"/>
      <geometry>
        <box size="0.03 0.03 0.52"/>
      </geometry>
      <material name="Mat Black 1">
        <color rgba="0.1 0.1 0.1 1.0"/>
      </material>
    </visual>
    <visual>
      <origin rpy="0 0 0" xyz="0.26749999999999996 -0.24 0"/>
      <geometry>
        <box size="0.03 0.03 0.52"/>
      </geometry>
      <material name="Mat Black 1">
        <color rgba="0.1 0.1 0.1 1.0"/>
      </material>
    </visual>
    <!-- Solid box collision -->
    <collision>
      <origin rpy="0 0 0" xyz="0 0 0"/>
      <geometry>
        <box size="0.565 0.51 0.52"/>
      </geometry>
    </collision>
  </link>
  <link name="support">
    <visual>
      <origin rpy="0 0 0" xyz="0 0 0"/>
      <geometry>
        <box size="0.155 0.721 0.02"/>
      </geometry>
      <material name="Mat Black 2">
        <color rgba="0.15 0.15 0.15 1.0"/>
      </material>
    </visual>
    <collision>
      <origin rpy="0 0 0" xyz="0 0 0"/>
      <geometry>
        <box size="0.155 0.721 0.02"/>
      </geometry>
    </collision>
  </link>
  <link name="cam_support">
    <visual>
      <origin rpy="0 0 0" xyz="-0.0625 0 0.3225"/>
      <geometry>
        <box size="0.03 0.03 0.675"/>
      </geometry>
      <material name="Mat Black 2">
        <color rgba="0.15 0.15 0.15 1.0"/>
      </material>
    </visual>
    <visual>
      <origin rpy="0 0 0" xyz="0.0625 0 0.3225"/>
      <geometry>
        <box size="0.03 0.03 0.675"/>
      </geometry>
      <material name="Mat Black 2">
        <color rgba="0.15 0.15 0.15 1.0"/>
      </material>
    </visual>
    <visual>
      <origin rpy="0 0 0" xyz="0 0 0.66"/>
      <geometry>
        <box size="0.155 0.03 0.03"/>
      </geometry>
      <material name="Mat Black 2">
        <color rgba="0.15 0.15 0.15 1.0"/>
      </material>
    </visual>
    <collision>
      <origin rpy="0 0 0" xyz="0 0 0"/>
      <geometry>
        <box size="0.155 0.03 0.675"/>
      </geometry>
    </collision>
  </link>
  <link name="camera">
    <visual>
      <origin rpy="0 0 0" xyz="0 0 0"/>
      <geometry>
        <mesh filename="package://avatar_robot_description/meshes/visual/Digital_Camera_USB.stl"/>
      </geometry>
      <material name="">
        <color rgba="0.3 0.3 0.3 1"/>
      </material>
    </visual>
    <collision>
      <origin rpy="0 0 0" xyz="0 0 0"/>
      <geometry>
        <mesh filename="package://avatar_robot_description/meshes/visual/Digital_Camera_USB.stl"/>
      </geometry>
    </collision>
  </link>
  <link name="screen">
    <visual>
      <origin rpy="0 0 0" xyz="-0.0001 0 0"/>
      <geometry>
        <box size="0.015 0.235 0.38"/>
      </geometry>
      <material name="Mat Black 2">
        <color rgba="0.15 0.15 0.15 1.0"/>
      </material>
    </visual>
    <visual>
      <origin rpy="0 0 0" xyz="0 0 0"/>
      <geometry>
        <box size="0.015 0.205 0.35"/>
      </geometry>
      <material name="">
        <color rgba="0.70 0.70 0.70 0.5"/>
      </material>
    </visual>
    <collision>
      <origin rpy="0 0 0" xyz="0 0 0"/>
      <geometry>
        <box size="0.015 0.225 0.37"/>
      </geometry>
    </collision>
  </link>
  <!-- joints -->
  <joint name="fixed_joint" type="fixed">
    <parent link="base"/>
    <child link="support"/>
    <origin rpy="0 0 0" xyz="0.2825 -0.018 0.27"/>
  </joint>
  <joint name="fixed_joint_2" type="fixed">
    <parent link="support"/>
    <child link="cam_support"/>
    <origin rpy="0 0 0" xyz="0 0.0505 0.01"/>
  </joint>
  <joint name="fixed_joint_3" type="fixed">
    <parent link="cam_support"/>
    <child link="camera"/>
    <origin rpy="0 1.75 0" xyz="0 -0.055 0.63"/>
  </joint>
  <joint name="fixed_joint_4" type="fixed">
    <parent link="cam_support"/>
    <child link="screen"/>
    <origin rpy="0 0 0" xyz="0.0875 -0.055 0.325"/>
  </joint>
  <joint name="right_panda_joint_support" type="fixed">
    <parent link="support"/>
    <child link="right_panda_link0"/>
    <origin rpy="0 0 0" xyz="0.06975 -0.27 0.01"/>
  </joint>
  <!-- sub-link defining detailed meshes for collision with environment -->
  <link name="right_panda_link0">
    <visual>
      <geometry>
        <mesh filename="package://avatar_robot_description/meshes/visual/link0.dae"/>
      </geometry>
    </visual>
    <collision>
      <geometry>
        <mesh filename="package://avatar_robot_description/meshes/collision/link0.stl"/>
      </geometry>
    </collision>
    <inertial>
      <origin rpy="0 0 0" xyz="-0.041018 -0.00014 0.049974"/>
      <mass value="0.629769"/>
      <inertia ixx="0.00315" ixy="8.2904e-07" ixz="0.00015" iyy="0.00388" iyz="8.2299e-06" izz="0.004285"/>
    </inertial>
  </link>
  <!-- sub-link defining coarse geometries of real robot's internal self-collision -->
  <link name="right_panda_link0_sc">
  </link>
  <!-- fixed joint between both sub-links -->
  <joint name="right_panda_link0_sc_joint" type="fixed">
    <origin rpy="0 0 0"/>
    <parent link="right_panda_link0"/>
    <child link="right_panda_link0_sc"/>
  </joint>
  <!-- sub-link defining detailed meshes for collision with environment -->
  <link name="right_panda_link1">
    <visual>
      <geometry>
        <mesh filename="package://avatar_robot_description/meshes/visual/link1.dae"/>
      </geometry>
    </visual>
    <collision>
      <geometry>
        <mesh filename="package://avatar_robot_description/meshes/collision/link1.stl"/>
      </geometry>
    </collision>
    <inertial>
      <origin rpy="0 0 0" xyz="0.003875 0.002081 -0.04762"/>
      <mass value="4.970684"/>
      <inertia ixx="0.70337" ixy="-0.000139" ixz="0.006772" iyy="0.70661" iyz="0.019169" izz="0.009117"/>
    </inertial>
  </link>
  <!-- sub-link defining coarse geometries of real robot's internal self-collision -->
  <link name="right_panda_link1_sc">
  </link>
  <!-- fixed joint between both sub-links -->
  <joint name="right_panda_link1_sc_joint" type="fixed">
    <origin rpy="0 0 0"/>
    <parent link="right_panda_link1"/>
    <child link="right_panda_link1_sc"/>
  </joint>
  <joint name="right_panda_joint1" type="revolute">
    <origin rpy="0 0 0" xyz="0 0 0.333"/>
    <parent link="right_panda_link0"/>
    <child link="right_panda_link1"/>
    <axis xyz="0 0 1"/>
    <limit effort="87.0" lower="-2.8973" upper="2.8973" velocity="2.175"/>
    <safety_controller k_position="100.0" k_velocity="40.0" soft_lower_limit="-2.8973" soft_upper_limit="2.8973"/>
    <dynamics D="1" K="7000" damping="0.003" friction="0.0" mu_coulomb="0" mu_viscous="16"/>
  </joint>
  <!-- sub-link defining detailed meshes for collision with environment -->
  <link name="right_panda_link2">
    <visual>
      <geometry>
        <mesh filename="package://avatar_robot_description/meshes/visual/link2.dae"/>
      </geometry>
    </visual>
    <collision>
      <geometry>
        <mesh filename="package://avatar_robot_description/meshes/collision/link2.stl"/>
      </geometry>
    </collision>
    <inertial>
      <origin rpy="0 0 0" xyz="-0.003141 -0.02872  0.003495"/>
      <mass value="0.646926"/>
      <inertia ixx="0.007962" ixy="-0.003925" ixz="0.010254" iyy="0.02811" iyz="0.000704" izz="0.025995"/>
    </inertial>
  </link>
  <!-- sub-link defining coarse geometries of real robot's internal self-collision -->
  <link name="right_panda_link2_sc">
  </link>
  <!-- fixed joint between both sub-links -->
  <joint name="right_panda_link2_sc_joint" type="fixed">
    <origin rpy="0 0 0"/>
    <parent link="right_panda_link2"/>
    <child link="right_panda_link2_sc"/>
  </joint>
  <joint name="right_panda_joint2" type="revolute">
    <origin rpy="-1.5707963267948966 0 0" xyz="0 0 0"/>
    <parent link="right_panda_link1"/>
    <child link="right_panda_link2"/>
    <axis xyz="0 0 1"/>
    <limit effort="87.0" lower="-1.7628" upper="1.7628" velocity="2.175"/>
    <safety_controller k_position="100.0" k_velocity="40.0" soft_lower_limit="-1.7628" soft_upper_limit="1.7628"/>
    <dynamics D="1" K="7000" damping="0.003" friction="0.0" mu_coulomb="0" mu_viscous="16"/>
  </joint>
  <!-- sub-link defining detailed meshes for collision with environment -->
  <link name="right_panda_link3">
    <visual>
      <geometry>
        <mesh filename="package://avatar_robot_description/meshes/visual/link3.dae"/>
      </geometry>
    </visual>
    <collision>
      <geometry>
        <mesh filename="package://avatar_robot_description/meshes/collision/link3.stl"/>
      </geometry>
    </collision>
    <inertial>
      <origin rpy="0 0 0" xyz="2.7518e-02 3.9252e-02 -6.6502e-02"/>
      <mass value="3.228604"/>
      <inertia ixx="0.037242" ixy="-0.004761" ixz="-0.011396" iyy="0.036155" iyz="-0.012805" izz="0.01083"/>
    </inertial>
  </link>
  <!-- sub-link defining coarse geometries of real robot's internal self-collision -->
  <link name="right_panda_link3_sc">
  </link>
  <!-- fixed joint between both sub-links -->
  <joint name="right_panda_link3_sc_joint" type="fixed">
    <origin rpy="0 0 0"/>
    <parent link="right_panda_link3"/>
    <child link="right_panda_link3_sc"/>
  </joint>
  <joint name="right_panda_joint3" type="revolute">
    <origin rpy="1.5707963267948966 0 0" xyz="0 -0.316 0"/>
    <parent link="right_panda_link2"/>
    <child link="right_panda_link3"/>
    <axis xyz="0 0 1"/>
    <limit effort="87.0" lower="-2.8973" upper="2.8973" velocity="2.175"/>
    <safety_controller k_position="100.0" k_velocity="40.0" soft_lower_limit="-2.8973" soft_upper_limit="2.8973"/>
    <dynamics D="1" K="7000" damping="0.003" friction="0.0" mu_coulomb="0" mu_viscous="16"/>
  </joint>
  <!-- sub-link defining detailed meshes for collision with environment -->
  <link name="right_panda_link4">
    <visual>
      <geometry>
        <mesh filename="package://avatar_robot_description/meshes/visual/link4.dae"/>
      </geometry>
    </visual>
    <collision>
      <geometry>
        <mesh filename="package://avatar_robot_description/meshes/collision/link4.stl"/>
      </geometry>
    </collision>
    <inertial>
      <origin rpy="0 0 0" xyz="-5.317e-02 1.04419e-01 2.7454e-02"/>
      <mass value="3.587895"/>
      <inertia ixx="0.025853" ixy="0.007796" ixz="-0.001332" iyy="0.019552" iyz="0.008641" izz="0.028323"/>
    </inertial>
  </link>
  <!-- sub-link defining coarse geometries of real robot's internal self-collision -->
  <link name="right_panda_link4_sc">
  </link>
  <!-- fixed joint between both sub-links -->
  <joint name="right_panda_link4_sc_joint" type="fixed">
    <origin rpy="0 0 0"/>
    <parent link="right_panda_link4"/>
    <child link="right_panda_link4_sc"/>
  </joint>
  <joint name="right_panda_joint4" type="revolute">
    <origin rpy="1.5707963267948966 0 0" xyz="0.0825 0 0"/>
    <parent link="right_panda_link3"/>
    <child link="right_panda_link4"/>
    <axis xyz="0 0 1"/>
    <limit effort="87.0" lower="-3.0718" upper="-0.0698" velocity="2.175"/>
    <safety_controller k_position="100.0" k_velocity="40.0" soft_lower_limit="-3.0718" soft_upper_limit="-0.0698"/>
    <dynamics D="1" K="7000" damping="0.003" friction="0.0" mu_coulomb="0" mu_viscous="16"/>
  </joint>
  <!-- sub-link defining detailed meshes for collision with environment -->
  <link name="right_panda_link5">
    <visual>
      <geometry>
        <mesh filename="package://avatar_robot_description/meshes/visual/link5.dae"/>
      </geometry>
    </visual>
    <collision>
      <geometry>
        <mesh filename="package://avatar_robot_description/meshes/collision/link5.stl"/>
      </geometry>
    </collision>
    <inertial>
      <origin rpy="0 0 0" xyz="-1.1953e-02 4.1065e-02 -3.8437e-02"/>
      <mass value="1.225946"/>
      <inertia ixx="0.035549" ixy="-0.002117" ixz="-0.004037" iyy="0.029474" iyz="0.000229" izz="0.008627"/>
    </inertial>
  </link>
  <!-- sub-link defining coarse geometries of real robot's internal self-collision -->
  <link name="right_panda_link5_sc">
  </link>
  <!-- fixed joint between both sub-links -->
  <joint name="right_panda_link5_sc_joint" type="fixed">
    <origin rpy="0 0 0"/>
    <parent link="right_panda_link5"/>
    <child link="right_panda_link5_sc"/>
  </joint>
  <joint name="right_panda_joint5" type="revolute">
    <origin rpy="-1.5707963267948966 0 0" xyz="-0.0825 0.384 0"/>
    <parent link="right_panda_link4"/>
    <child link="right_panda_link5"/>
    <axis xyz="0 0 1"/>
    <limit effort="12.0" lower="-2.8973" upper="2.8973" velocity="2.61"/>
    <safety_controller k_position="100.0" k_velocity="40.0" soft_lower_limit="-2.8973" soft_upper_limit="2.8973"/>
    <dynamics D="1" K="7000" damping="0.003" friction="0.0" mu_coulomb="0" mu_viscous="16"/>
  </joint>
  <!-- sub-link defining detailed meshes for collision with environment -->
  <link name="right_panda_link6">
    <visual>
      <geometry>
        <mesh filename="package://avatar_robot_description/meshes/visual/link6.dae"/>
      </geometry>
    </visual>
    <collision>
      <geometry>
        <mesh filename="package://avatar_robot_description/meshes/collision/link6.stl"/>
      </geometry>
    </collision>
    <inertial>
      <origin rpy="0 0 0" xyz="6.0149e-02 -1.4117e-02 -1.0517e-02"/>
      <mass value="1.666555"/>
      <inertia ixx="0.001964" ixy="0.000109" ixz="-0.001158" iyy="0.004354" iyz="0.000341" izz="0.005433"/>
    </inertial>
  </link>
  <!-- sub-link defining coarse geometries of real robot's internal self-collision -->
  <link name="right_panda_link6_sc">
  </link>
  <!-- fixed joint between both sub-links -->
  <joint name="right_panda_link6_sc_joint" type="fixed">
    <origin rpy="0 0 0"/>
    <parent link="right_panda_link6"/>
    <child link="right_panda_link6_sc"/>
  </joint>
  <joint name="right_panda_joint6" type="revolute">
    <origin rpy="1.5707963267948966 0 0" xyz="0 0 0"/>
    <parent link="right_panda_link5"/>
    <child link="right_panda_link6"/>
    <axis xyz="0 0 1"/>
    <limit effort="12.0" lower="-0.0175" upper="3.7525" velocity="2.61"/>
    <safety_controller k_position="100.0" k_velocity="40.0" soft_lower_limit="-0.0175" soft_upper_limit="3.7525"/>
    <dynamics D="1" K="7000" damping="0.003" friction="0.0" mu_coulomb="0" mu_viscous="16"/>
  </joint>
  <!-- sub-link defining detailed meshes for collision with environment -->
  <link name="right_panda_link7">
    <visual>
      <geometry>
        <mesh filename="package://avatar_robot_description/meshes/visual/link7.dae"/>
      </geometry>
    </visual>
    <collision>
      <geometry>
        <mesh filename="package://avatar_robot_description/meshes/collision/link7.stl"/>
      </geometry>
    </collision>
    <inertial>
      <origin rpy="0 0 0" xyz="1.0517e-02 -4.252e-03 6.1597e-02"/>
      <mass value="0.735522"/>
      <inertia ixx="0.012516" ixy="-0.000428" ixz="-0.001196" iyy="0.010027" iyz="-0.000741" izz="0.004815"/>
    </inertial>
  </link>
  <!-- sub-link defining coarse geometries of real robot's internal self-collision -->
  <link name="right_panda_link7_sc">
  </link>
  <!-- fixed joint between both sub-links -->
  <joint name="right_panda_link7_sc_joint" type="fixed">
    <origin rpy="0 0 0.7853981633974483"/>
    <parent link="right_panda_link7"/>
    <child link="right_panda_link7_sc"/>
  </joint>
  <joint name="right_panda_joint7" type="revolute">
    <origin rpy="1.5707963267948966 0 0" xyz="0.088 0 0"/>
    <parent link="right_panda_link6"/>
    <child link="right_panda_link7"/>
    <axis xyz="0 0 1"/>
    <limit effort="12.0" lower="-2.8973" upper="2.8973" velocity="2.61"/>
    <safety_controller k_position="100.0" k_velocity="40.0" soft_lower_limit="-2.8973" soft_upper_limit="2.8973"/>
    <dynamics D="1" K="7000" damping="0.003" friction="0.0" mu_coulomb="0" mu_viscous="16"/>
  </joint>
  <link name="right_panda_link8"/>
  <joint name="right_panda_joint8" type="fixed">
    <origin rpy="0 0 0" xyz="0 0 0.107"/>
    <parent link="right_panda_link7"/>
    <child link="right_panda_link8"/>
  </joint>
  <link name="right_thumb_base">
    <inertial>
      <mass value="0.5"/>
      <inertia ixx="4E-5" ixy="0.0" ixz="0.0" iyy="4E-5" iyz="0.0" izz="4E-5"/>
    </inertial>
    <visual>
      <origin rpy="0 0 0" xyz="0 0 0"/>
      <geometry>
        <mesh filename="package://avatar_gripper_description/meshes/right/thumb_base_extra.STL"/>
      </geometry>
      <material name="">
        <color rgba="0.9 0.9 0.9 1"/>
      </material>
    </visual>
    <collision>
      <origin rpy="0 0 0" xyz="0 0 0"/>
      <geometry>
        <mesh filename="package://avatar_gripper_description/meshes/right/thumb_base_extra.STL"/>
      </geometry>
    </collision>
  </link>
  <link name="right_thumb_knuckle">
    <inertial>
      <mass value="0.5"/>
      <inertia ixx="4E-5" ixy="0.0" ixz="0.0" iyy="4E-5" iyz="0.0" izz="4E-5"/>
    </inertial>
    <visual>
      <origin rpy="0 0 0" xyz="0 0 0"/>
      <geometry>
        <mesh filename="package://avatar_gripper_description/meshes/right/thumb_knuckle.STL"/>
      </geometry>
      <material name="">
        <color rgba="0.9 0.9 0.9 1"/>
      </material>
    </visual>
    <collision>
      <origin rpy="0 0 0" xyz="0 0 0"/>
      <geometry>
        <mesh filename="package://avatar_gripper_description/meshes/right/thumb_knuckle.STL"/>
      </geometry>
    </collision>
  </link>
  <joint name="right_thumb_knuckle_joint" type="revolute">
    <origin rpy="0 2.75 0" xyz="0 0 0"/>
    <parent link="right_thumb_base"/>
    <child link="right_thumb_knuckle"/>
    <axis xyz="0 1 0"/>
    <limit effort="1000" lower="-1.0" upper="0.4" velocity="2.0"/>
  </joint>
  <link name="right_thumb_finger">
    <inertial>
      <mass value="0.5"/>
      <inertia ixx="4E-5" ixy="0.0" ixz="0.0" iyy="4E-5" iyz="0.0" izz="4E-5"/>
    </inertial>
    <visual>
      <origin rpy="0 0 0" xyz="0 0 0"/>
      <geometry>
        <mesh filename="package://avatar_gripper_description/meshes/right/thumb_fingertip.STL"/>
      </geometry>
      <material name="">
        <color rgba="0.9 0.9 0.9 1"/>
      </material>
    </visual>
    <collision>
      <origin rpy="0 0 0" xyz="0 0 0"/>
      <geometry>
        <mesh filename="package://avatar_gripper_description/meshes/right/thumb_fingertip.STL"/>
      </geometry>
    </collision>
  </link>
  <joint name="right_thumb_finger_joint" type="revolute">
    <origin rpy="0 0.57 0" xyz="0.04568 0 0.01106"/>
    <parent link="right_thumb_knuckle"/>
    <child link="right_thumb_finger"/>
    <axis xyz="0 1 0"/>
    <limit effort="1000" lower="-0.8" upper="0" velocity="2.0"/>
  </joint>
  <link name="right_thumb_swivel_link">
    <inertial>
      <mass value="0.1"/>
      <inertia ixx="4E-5" ixy="0.0" ixz="0.0" iyy="4E-5" iyz="0.0" izz="4E-5"/>
    </inertial>
    <visual>
      <origin rpy="0 0 0" xyz="0 0 0"/>
      <geometry>
        <mesh filename="package://avatar_gripper_description/meshes/right/thumb_swivel_link.STL"/>
      </geometry>
      <material name="">
        <color rgba="0.9 0.9 0.9 1"/>
      </material>
    </visual>
    <collision>
      <origin rpy="0 0 0" xyz="0 0 0"/>
      <geometry>
        <mesh filename="package://avatar_gripper_description/meshes/right/thumb_swivel_link.STL"/>
      </geometry>
    </collision>
  </link>
  <joint name="right_thumb_swivel_joint" type="revolute">
    <origin rpy="0 0 0" xyz="0 0 0.0173"/>
    <parent link="right_index_base_connector"/>
    <child link="right_thumb_swivel_link"/>
    <axis xyz="0 0 1"/>
    <limit effort="1000" lower="0" upper="1.7" velocity="2.0"/>
  </joint>
  <joint name="right_thumb_base_swivel_joint" type="fixed">
    <origin rpy="0 0 0" xyz="-0.03742 0 0.05089"/>
    <parent link="right_thumb_swivel_link"/>
    <child link="right_thumb_base"/>
  </joint>
  <link name="right_index_base_connector">
    <inertial>
      <mass value="0.02"/>
      <inertia ixx="4E-5" ixy="0.0" ixz="0.0" iyy="4E-5" iyz="0.0" izz="4E-5"/>
    </inertial>
    <visual>
      <origin rpy="0 0 0" xyz="0 0 0"/>
      <geometry>
        <mesh filename="package://avatar_gripper_description/meshes/right/index_base_connector.STL"/>
      </geometry>
      <material name="">
        <color rgba="0.9 0.9 0.9 1"/>
      </material>
    </visual>
  </link>
  <link name="right_index_knuckle">
    <inertial>
      <mass value="0.5"/>
      <inertia ixx="4E-5" ixy="0.0" ixz="0.0" iyy="4E-5" iyz="0.0" izz="4E-5"/>
    </inertial>
    <visual>
      <origin rpy="0 0 0" xyz="0 0 0"/>
      <geometry>
        <mesh filename="package://avatar_gripper_description/meshes/right/index_knuckle.STL"/>
      </geometry>
      <material name="">
        <color rgba="0.9 0.9 0.9 1"/>
      </material>
    </visual>
    <collision>
      <origin rpy="0 0 0" xyz="0 0 0"/>
      <geometry>
        <mesh filename="package://avatar_gripper_description/meshes/right/index_knuckle.STL"/>
      </geometry>
    </collision>
  </link>
  <joint name="right_index_knuckle_joint" type="revolute">
    <origin rpy="1.94428593 1.07478656 1.98996937" xyz="-0.021564878 0.008545 -0.0024358"/>
    <parent link="right_index_base_connector"/>
    <child link="right_index_knuckle"/>
    <axis xyz="0 0 1"/>
    <limit effort="1000" lower="-0.8" upper="0" velocity="2.0"/>
  </joint>
  <link name="right_index_fingertip">
    <inertial>
      <mass value="0.5"/>
      <inertia ixx="4E-5" ixy="0.0" ixz="0.0" iyy="4E-5" iyz="0.0" izz="4E-5"/>
    </inertial>
    <visual>
      <origin rpy="0 0 0" xyz="0 0 0"/>
      <geometry>
        <mesh filename="package://avatar_gripper_description/meshes/right/index_fingertip.STL"/>
      </geometry>
      <material name="">
        <color rgba="0.9 0.9 0.9 1"/>
      </material>
    </visual>
    <collision>
      <origin rpy="0 0 0" xyz="0 0 0"/>
      <geometry>
        <mesh filename="package://avatar_gripper_description/meshes/right/index_fingertip.STL"/>
      </geometry>
    </collision>
  </link>
  <joint name="right_index_fingertip_joint" type="revolute">
    <origin rpy="0 0 -0.35" xyz="0.0353829 -0.02780 0"/>
    <parent link="right_index_knuckle"/>
    <child link="right_index_fingertip"/>
    <axis xyz="0 0 1"/>
    <limit effort="1000" lower="-0.8" upper="0" velocity="2.0"/>
  </joint>
  <link name="right_middle_knuckle">
    <inertial>
      <mass value="0.5"/>
      <inertia ixx="4E-5" ixy="0.0" ixz="0.0" iyy="4E-5" iyz="0.0" izz="4E-5"/>
    </inertial>
    <visual>
      <origin rpy="0 0 0" xyz="0 0 0"/>
      <geometry>
        <mesh filename="package://avatar_gripper_description/meshes/right/index_knuckle.STL"/>
      </geometry>
      <material name="">
        <color rgba="0.9 0.9 0.9 1"/>
      </material>
    </visual>
    <collision>
      <origin rpy="0 0 0" xyz="0 0 0"/>
      <geometry>
        <mesh filename="package://avatar_gripper_description/meshes/right/index_knuckle.STL"/>
      </geometry>
    </collision>
  </link>
  <joint name="right_middle_knuckle_joint" type="revolute">
    <origin rpy="1.19730672 1.07478656 1.15162329" xyz="0.02156 0.008545 -0.0024358"/>
    <parent link="right_index_base_connector"/>
    <child link="right_middle_knuckle"/>
    <axis xyz="0 0 1"/>
    <limit effort="1000" lower="-0.8" upper="0" velocity="2.0"/>
  </joint>
  <link name="right_middle_fingertip">
    <inertial>
      <mass value="0.5"/>
      <inertia ixx="4E-5" ixy="0.0" ixz="0.0" iyy="4E-5" iyz="0.0" izz="4E-5"/>
    </inertial>
    <visual>
      <origin rpy="0 0 0" xyz="0 0 0"/>
      <geometry>
        <mesh filename="package://avatar_gripper_description/meshes/right/index_fingertip.STL"/>
      </geometry>
      <material name="">
        <color rgba="0.9 0.9 0.9 1"/>
      </material>
    </visual>
    <collision>
      <origin rpy="0 0 0" xyz="0 0 0"/>
      <geometry>
        <mesh filename="package://avatar_gripper_description/meshes/right/index_fingertip.STL"/>
      </geometry>
    </collision>
  </link>
  <joint name="right_middle_fingertip_joint" type="revolute">
    <origin rpy="0 0 -0.35" xyz="0.0353829 -0.02780 0"/>
    <parent link="right_middle_knuckle"/>
    <child link="right_middle_fingertip"/>
    <axis xyz="0 0 1"/>
    <limit effort="1000" lower="-0.8" upper="0" velocity="2.0"/>
  </joint>
  <link name="right_gripper_base">
    <inertial>
      <mass value="2.0"/>
      <inertia ixx="7.11E-3" ixy="0.0" ixz="0.0" iyy="7.11E-3" iyz="0.0" izz="7.11E-3"/>
    </inertial>
    <visual>
      <origin rpy="0 0 0" xyz="0 0 0"/>
      <geometry>
        <mesh filename="package://avatar_gripper_description/meshes/right/gripper_base.STL"/>
      </geometry>
      <material name="">
        <color rgba="0.9 0.9 0.7 1"/>
      </material>
    </visual>
    <collision>
      <origin rpy="0 0 0" xyz="0 0 -0.03"/>
      <geometry>
        <box size="0.1 0.1 0.06"/>
      </geometry>
    </collision>
  </link>
  <joint name="right_gripper_base_joint" type="fixed">
    <origin rpy="1.57 0 0" xyz="0.00736 0.139 -0.066017"/>
    <parent link="right_gripper_base"/>
    <child link="right_index_base_connector"/>
  </joint>
  <link name="right_thumb_flex_motor">
    <inertial>
      <mass value="0.25"/>
      <inertia ixx="1.463E-04" ixy="0" ixz="0" iyy="1.463E-04" iyz="0" izz="1.463E-04"/>
    </inertial>
    <visual>
      <origin rpy="0 0 0" xyz="0 0 0"/>
      <geometry>
        <cylinder length="0.01" radius="0.02"/>
      </geometry>
    </visual>
  </link>
  <joint name="right_thumb_flex_motor_joint" type="revolute">
    <origin rpy="0 0 0" xyz="-0.05 -0.3 0"/>
    <parent link="right_gripper_base"/>
    <child link="right_thumb_flex_motor"/>
    <axis xyz="0 0 1"/>
    <limit effort="1000" lower="-2.3" upper="-0.08" velocity="2.0"/>
  </joint>
  <link name="right_thumb_swivel_motor">
    <inertial>
      <mass value="0.25"/>
      <inertia ixx="1.463E-04" ixy="0" ixz="0" iyy="1.463E-04" iyz="0" izz="1.463E-04"/>
    </inertial>
    <visual>
      <origin rpy="0 0 0" xyz="0 0 0"/>
      <geometry>
        <cylinder length="0.01" radius="0.02"/>
      </geometry>
    </visual>
  </link>
  <joint name="right_thumb_swivel_motor_joint" type="revolute">
    <origin rpy="0 0 0" xyz="-0.1 -0.3 0"/>
    <parent link="right_gripper_base"/>
    <child link="right_thumb_swivel_motor"/>
    <axis xyz="0 0 1"/>
    <limit effort="1000" lower="-2.3" upper="-0.05" velocity="2.0"/>
  </joint>
  <link name="right_index_flex_motor">
    <inertial>
      <mass value="0.25"/>
      <inertia ixx="1.463E-04" ixy="0" ixz="0" iyy="1.463E-04" iyz="0" izz="1.463E-04"/>
    </inertial>
    <visual>
      <origin rpy="0 0 0" xyz="0 0 0"/>
      <geometry>
        <cylinder length="0.01" radius="0.02"/>
      </geometry>
    </visual>
  </link>
  <joint name="right_index_flex_motor_joint" type="revolute">
    <origin rpy="0 0 0" xyz="0 -0.3 0"/>
    <parent link="right_gripper_base"/>
    <child link="right_index_flex_motor"/>
    <axis xyz="0 0 1"/>
    <limit effort="1000" lower="-2.3" upper="-0.08" velocity="2.0"/>
  </joint>
  <joint name="right_panda_gripper_joint" type="fixed">
    <parent link="right_panda_link8"/>
    <child link="right_gripper_base"/>
    <origin rpy="0 3.141592653589793 -0.7853981633974483" xyz="0 0 0"/>
  </joint>
  <joint name="left_panda_joint_support" type="fixed">
    <parent link="support"/>
    <child link="left_panda_link0"/>
    <origin rpy="0 0 0" xyz="0.06975 0.27 0.01"/>
  </joint>
  <!-- sub-link defining detailed meshes for collision with environment -->
  <link name="left_panda_link0">
    <visual>
      <geometry>
        <mesh filename="package://avatar_robot_description/meshes/visual/link0.dae"/>
      </geometry>
    </visual>
    <collision>
      <geometry>
        <mesh filename="package://avatar_robot_description/meshes/collision/link0.stl"/>
      </geometry>
    </collision>
    <inertial>
      <origin rpy="0 0 0" xyz="-0.041018 -0.00014 0.049974"/>
      <mass value="0.629769"/>
      <inertia ixx="0.00315" ixy="8.2904e-07" ixz="0.00015" iyy="0.00388" iyz="8.2299e-06" izz="0.004285"/>
    </inertial>
  </link>
  <!-- sub-link defining coarse geometries of real robot's internal self-collision -->
  <link name="left_panda_link0_sc">
  </link>
  <!-- fixed joint between both sub-links -->
  <joint name="left_panda_link0_sc_joint" type="fixed">
    <origin rpy="0 0 0"/>
    <parent link="left_panda_link0"/>
    <child link="left_panda_link0_sc"/>
  </joint>
  <!-- sub-link defining detailed meshes for collision with environment -->
  <link name="left_panda_link1">
    <visual>
      <geometry>
        <mesh filename="package://avatar_robot_description/meshes/visual/link1.dae"/>
      </geometry>
    </visual>
    <collision>
      <geometry>
        <mesh filename="package://avatar_robot_description/meshes/collision/link1.stl"/>
      </geometry>
    </collision>
    <inertial>
      <origin rpy="0 0 0" xyz="0.003875 0.002081 -0.04762"/>
      <mass value="4.970684"/>
      <inertia ixx="0.70337" ixy="-0.000139" ixz="0.006772" iyy="0.70661" iyz="0.019169" izz="0.009117"/>
    </inertial>
  </link>
  <!-- sub-link defining coarse geometries of real robot's internal self-collision -->
  <link name="left_panda_link1_sc">
  </link>
  <!-- fixed joint between both sub-links -->
  <joint name="left_panda_link1_sc_joint" type="fixed">
    <origin rpy="0 0 0"/>
    <parent link="left_panda_link1"/>
    <child link="left_panda_link1_sc"/>
  </joint>
  <joint name="left_panda_joint1" type="revolute">
    <origin rpy="0 0 0" xyz="0 0 0.333"/>
    <parent link="left_panda_link0"/>
    <child link="left_panda_link1"/>
    <axis xyz="0 0 1"/>
    <limit effort="87.0" lower="-2.8973" upper="2.8973" velocity="2.175"/>
    <safety_controller k_position="100.0" k_velocity="40.0" soft_lower_limit="-2.8973" soft_upper_limit="2.8973"/>
    <dynamics D="1" K="7000" damping="0.003" friction="0.0" mu_coulomb="0" mu_viscous="16"/>
  </joint>
  <!-- sub-link defining detailed meshes for collision with environment -->
  <link name="left_panda_link2">
    <visual>
      <geometry>
        <mesh filename="package://avatar_robot_description/meshes/visual/link2.dae"/>
      </geometry>
    </visual>
    <collision>
      <geometry>
        <mesh filename="package://avatar_robot_description/meshes/collision/link2.stl"/>
      </geometry>
    </collision>
    <inertial>
      <origin rpy="0 0 0" xyz="-0.003141 -0.02872  0.003495"/>
      <mass value="0.646926"/>
      <inertia ixx="0.007962" ixy="-0.003925" ixz="0.010254" iyy="0.02811" iyz="0.000704" izz="0.025995"/>
    </inertial>
  </link>
  <!-- sub-link defining coarse geometries of real robot's internal self-collision -->
  <link name="left_panda_link2_sc">
  </link>
  <!-- fixed joint between both sub-links -->
  <joint name="left_panda_link2_sc_joint" type="fixed">
    <origin rpy="0 0 0"/>
    <parent link="left_panda_link2"/>
    <child link="left_panda_link2_sc"/>
  </joint>
  <joint name="left_panda_joint2" type="revolute">
    <origin rpy="-1.5707963267948966 0 0" xyz="0 0 0"/>
    <parent link="left_panda_link1"/>
    <child link="left_panda_link2"/>
    <axis xyz="0 0 1"/>
    <limit effort="87.0" lower="-1.7628" upper="1.7628" velocity="2.175"/>
    <safety_controller k_position="100.0" k_velocity="40.0" soft_lower_limit="-1.7628" soft_upper_limit="1.7628"/>
    <dynamics D="1" K="7000" damping="0.003" friction="0.0" mu_coulomb="0" mu_viscous="16"/>
  </joint>
  <!-- sub-link defining detailed meshes for collision with environment -->
  <link name="left_panda_link3">
    <visual>
      <geometry>
        <mesh filename="package://avatar_robot_description/meshes/visual/link3.dae"/>
      </geometry>
    </visual>
    <collision>
      <geometry>
        <mesh filename="package://avatar_robot_description/meshes/collision/link3.stl"/>
      </geometry>
    </collision>
    <inertial>
      <origin rpy="0 0 0" xyz="2.7518e-02 3.9252e-02 -6.6502e-02"/>
      <mass value="3.228604"/>
      <inertia ixx="0.037242" ixy="-0.004761" ixz="-0.011396" iyy="0.036155" iyz="-0.012805" izz="0.01083"/>
    </inertial>
  </link>
  <!-- sub-link defining coarse geometries of real robot's internal self-collision -->
  <link name="left_panda_link3_sc">
  </link>
  <!-- fixed joint between both sub-links -->
  <joint name="left_panda_link3_sc_joint" type="fixed">
    <origin rpy="0 0 0"/>
    <parent link="left_panda_link3"/>
    <child link="left_panda_link3_sc"/>
  </joint>
  <joint name="left_panda_joint3" type="revolute">
    <origin rpy="1.5707963267948966 0 0" xyz="0 -0.316 0"/>
    <parent link="left_panda_link2"/>
    <child link="left_panda_link3"/>
    <axis xyz="0 0 1"/>
    <limit effort="87.0" lower="-2.8973" upper="2.8973" velocity="2.175"/>
    <safety_controller k_position="100.0" k_velocity="40.0" soft_lower_limit="-2.8973" soft_upper_limit="2.8973"/>
    <dynamics D="1" K="7000" damping="0.003" friction="0.0" mu_coulomb="0" mu_viscous="16"/>
  </joint>
  <!-- sub-link defining detailed meshes for collision with environment -->
  <link name="left_panda_link4">
    <visual>
      <geometry>
        <mesh filename="package://avatar_robot_description/meshes/visual/link4.dae"/>
      </geometry>
    </visual>
    <collision>
      <geometry>
        <mesh filename="package://avatar_robot_description/meshes/collision/link4.stl"/>
      </geometry>
    </collision>
    <inertial>
      <origin rpy="0 0 0" xyz="-5.317e-02 1.04419e-01 2.7454e-02"/>
      <mass value="3.587895"/>
      <inertia ixx="0.025853" ixy="0.007796" ixz="-0.001332" iyy="0.019552" iyz="0.008641" izz="0.028323"/>
    </inertial>
  </link>
  <!-- sub-link defining coarse geometries of real robot's internal self-collision -->
  <link name="left_panda_link4_sc">
  </link>
  <!-- fixed joint between both sub-links -->
  <joint name="left_panda_link4_sc_joint" type="fixed">
    <origin rpy="0 0 0"/>
    <parent link="left_panda_link4"/>
    <child link="left_panda_link4_sc"/>
  </joint>
  <joint name="left_panda_joint4" type="revolute">
    <origin rpy="1.5707963267948966 0 0" xyz="0.0825 0 0"/>
    <parent link="left_panda_link3"/>
    <child link="left_panda_link4"/>
    <axis xyz="0 0 1"/>
    <limit effort="87.0" lower="-3.0718" upper="-0.0698" velocity="2.175"/>
    <safety_controller k_position="100.0" k_velocity="40.0" soft_lower_limit="-3.0718" soft_upper_limit="-0.0698"/>
    <dynamics D="1" K="7000" damping="0.003" friction="0.0" mu_coulomb="0" mu_viscous="16"/>
  </joint>
  <!-- sub-link defining detailed meshes for collision with environment -->
  <link name="left_panda_link5">
    <visual>
      <geometry>
        <mesh filename="package://avatar_robot_description/meshes/visual/link5.dae"/>
      </geometry>
    </visual>
    <collision>
      <geometry>
        <mesh filename="package://avatar_robot_description/meshes/collision/link5.stl"/>
      </geometry>
    </collision>
    <inertial>
      <origin rpy="0 0 0" xyz="-1.1953e-02 4.1065e-02 -3.8437e-02"/>
      <mass value="1.225946"/>
      <inertia ixx="0.035549" ixy="-0.002117" ixz="-0.004037" iyy="0.029474" iyz="0.000229" izz="0.008627"/>
    </inertial>
  </link>
  <!-- sub-link defining coarse geometries of real robot's internal self-collision -->
  <link name="left_panda_link5_sc">
  </link>
  <!-- fixed joint between both sub-links -->
  <joint name="left_panda_link5_sc_joint" type="fixed">
    <origin rpy="0 0 0"/>
    <parent link="left_panda_link5"/>
    <child link="left_panda_link5_sc"/>
  </joint>
  <joint name="left_panda_joint5" type="revolute">
    <origin rpy="-1.5707963267948966 0 0" xyz="-0.0825 0.384 0"/>
    <parent link="left_panda_link4"/>
    <child link="left_panda_link5"/>
    <axis xyz="0 0 1"/>
    <limit effort="12.0" lower="-2.8973" upper="2.8973" velocity="2.61"/>
    <safety_controller k_position="100.0" k_velocity="40.0" soft_lower_limit="-2.8973" soft_upper_limit="2.8973"/>
    <dynamics D="1" K="7000" damping="0.003" friction="0.0" mu_coulomb="0" mu_viscous="16"/>
  </joint>
  <!-- sub-link defining detailed meshes for collision with environment -->
  <link name="left_panda_link6">
    <visual>
      <geometry>
        <mesh filename="package://avatar_robot_description/meshes/visual/link6.dae"/>
      </geometry>
    </visual>
    <collision>
      <geometry>
        <mesh filename="package://avatar_robot_description/meshes/collision/link6.stl"/>
      </geometry>
    </collision>
    <inertial>
      <origin rpy="0 0 0" xyz="6.0149e-02 -1.4117e-02 -1.0517e-02"/>
      <mass value="1.666555"/>
      <inertia ixx="0.001964" ixy="0.000109" ixz="-0.001158" iyy="0.004354" iyz="0.000341" izz="0.005433"/>
    </inertial>
  </link>
  <!-- sub-link defining coarse geometries of real robot's internal self-collision -->
  <link name="left_panda_link6_sc">
  </link>
  <!-- fixed joint between both sub-links -->
  <joint name="left_panda_link6_sc_joint" type="fixed">
    <origin rpy="0 0 0"/>
    <parent link="left_panda_link6"/>
    <child link="left_panda_link6_sc"/>
  </joint>
  <joint name="left_panda_joint6" type="revolute">
    <origin rpy="1.5707963267948966 0 0" xyz="0 0 0"/>
    <parent link="left_panda_link5"/>
    <child link="left_panda_link6"/>
    <axis xyz="0 0 1"/>
    <limit effort="12.0" lower="-0.0175" upper="3.7525" velocity="2.61"/>
    <safety_controller k_position="100.0" k_velocity="40.0" soft_lower_limit="-0.0175" soft_upper_limit="3.7525"/>
    <dynamics D="1" K="7000" damping="0.003" friction="0.0" mu_coulomb="0" mu_viscous="16"/>
  </joint>
  <!-- sub-link defining detailed meshes for collision with environment -->
  <link name="left_panda_link7">
    <visual>
      <geometry>
        <mesh filename="package://avatar_robot_description/meshes/visual/link7.dae"/>
      </geometry>
    </visual>
    <collision>
      <geometry>
        <mesh filename="package://avatar_robot_description/meshes/collision/link7.stl"/>
      </geometry>
    </collision>
    <inertial>
      <origin rpy="0 0 0" xyz="1.0517e-02 -4.252e-03 6.1597e-02"/>
      <mass value="0.735522"/>
      <inertia ixx="0.012516" ixy="-0.000428" ixz="-0.001196" iyy="0.010027" iyz="-0.000741" izz="0.004815"/>
    </inertial>
  </link>
  <!-- sub-link defining coarse geometries of real robot's internal self-collision -->
  <link name="left_panda_link7_sc">
  </link>
  <!-- fixed joint between both sub-links -->
  <joint name="left_panda_link7_sc_joint" type="fixed">
    <origin rpy="0 0 0.7853981633974483"/>
    <parent link="left_panda_link7"/>
    <child link="left_panda_link7_sc"/>
  </joint>
  <joint name="left_panda_joint7" type="revolute">
    <origin rpy="1.5707963267948966 0 0" xyz="0.088 0 0"/>
    <parent link="left_panda_link6"/>
    <child link="left_panda_link7"/>
    <axis xyz="0 0 1"/>
    <limit effort="12.0" lower="-2.8973" upper="2.8973" velocity="2.61"/>
    <safety_controller k_position="100.0" k_velocity="40.0" soft_lower_limit="-2.8973" soft_upper_limit="2.8973"/>
    <dynamics D="1" K="7000" damping="0.003" friction="0.0" mu_coulomb="0" mu_viscous="16"/>
  </joint>
  <link name="left_panda_link8"/>
  <joint name="left_panda_joint8" type="fixed">
    <origin rpy="0 0 0" xyz="0 0 0.107"/>
    <parent link="left_panda_link7"/>
    <child link="left_panda_link8"/>
  </joint>
  <link name="left_thumb_base">
    <inertial>
      <mass value="0.5"/>
      <inertia ixx="4E-5" ixy="0.0" ixz="0.0" iyy="4E-5" iyz="0.0" izz="4E-5"/>
    </inertial>
    <visual>
      <origin rpy="0 0 0" xyz="0 0 0"/>
      <geometry>
        <mesh filename="package://avatar_gripper_description/meshes/left/thumb_base_extra.STL"/>
      </geometry>
      <material name="">
        <color rgba="0.9 0.9 0.9 1"/>
      </material>
    </visual>
    <collision>
      <origin rpy="0 0 0" xyz="0 0 0"/>
      <geometry>
        <mesh filename="package://avatar_gripper_description/meshes/left/thumb_base_extra.STL"/>
      </geometry>
    </collision>
  </link>
  <link name="left_thumb_knuckle">
    <inertial>
      <mass value="0.5"/>
      <inertia ixx="4E-5" ixy="0.0" ixz="0.0" iyy="4E-5" iyz="0.0" izz="4E-5"/>
    </inertial>
    <visual>
      <origin rpy="0 0 0" xyz="0 0 0"/>
      <geometry>
        <mesh filename="package://avatar_gripper_description/meshes/left/thumb_knuckle.STL"/>
      </geometry>
      <material name="">
        <color rgba="0.9 0.9 0.9 1"/>
      </material>
    </visual>
    <collision>
      <origin rpy="0 0 0" xyz="0 0 0"/>
      <geometry>
        <mesh filename="package://avatar_gripper_description/meshes/left/thumb_knuckle.STL"/>
      </geometry>
    </collision>
  </link>
  <joint name="left_thumb_knuckle_joint" type="revolute">
    <origin rpy="0 2.75 0" xyz="0 0 0"/>
    <parent link="left_thumb_base"/>
    <child link="left_thumb_knuckle"/>
    <axis xyz="0 1 0"/>
    <limit effort="1000" lower="-1.0" upper="0.4" velocity="2.0"/>
  </joint>
  <link name="left_thumb_finger">
    <inertial>
      <mass value="0.5"/>
      <inertia ixx="4E-5" ixy="0.0" ixz="0.0" iyy="4E-5" iyz="0.0" izz="4E-5"/>
    </inertial>
    <visual>
      <origin rpy="0 0 0" xyz="0 0 0"/>
      <geometry>
        <mesh filename="package://avatar_gripper_description/meshes/left/thumb_fingertip.STL"/>
      </geometry>
      <material name="">
        <color rgba="0.9 0.9 0.9 1"/>
      </material>
    </visual>
    <collision>
      <origin rpy="0 0 0" xyz="0 0 0"/>
      <geometry>
        <mesh filename="package://avatar_gripper_description/meshes/left/thumb_fingertip.STL"/>
      </geometry>
    </collision>
  </link>
  <joint name="left_thumb_finger_joint" type="revolute">
    <origin rpy="0 0.57 0" xyz="0.04568 0 0.01106"/>
    <parent link="left_thumb_knuckle"/>
    <child link="left_thumb_finger"/>
    <axis xyz="0 1 0"/>
    <limit effort="1000" lower="-0.8" upper="0" velocity="2.0"/>
  </joint>
  <link name="left_thumb_swivel_link">
    <inertial>
      <mass value="0.1"/>
      <inertia ixx="4E-5" ixy="0.0" ixz="0.0" iyy="4E-5" iyz="0.0" izz="4E-5"/>
    </inertial>
    <visual>
      <origin rpy="0 0 0" xyz="0 0 0"/>
      <geometry>
        <mesh filename="package://avatar_gripper_description/meshes/left/thumb_swivel_link.STL"/>
      </geometry>
      <material name="">
        <color rgba="0.9 0.9 0.9 1"/>
      </material>
    </visual>
    <collision>
      <origin rpy="0 0 0" xyz="0 0 0"/>
      <geometry>
        <mesh filename="package://avatar_gripper_description/meshes/left/thumb_swivel_link.STL"/>
      </geometry>
    </collision>
  </link>
  <joint name="left_thumb_swivel_joint" type="revolute">
    <origin rpy="0 0 0.7853" xyz="0 0 0.0173"/>
    <parent link="left_index_base_connector"/>
    <child link="left_thumb_swivel_link"/>
    <axis xyz="0 0 1"/>
    <limit effort="1000" lower="0" upper="1.7" velocity="2.0"/>
  </joint>
  <joint name="left_thumb_base_swivel_joint" type="fixed">
    <origin rpy="0 0 0" xyz="-0.03742 0 0.05089"/>
    <parent link="left_thumb_swivel_link"/>
    <child link="left_thumb_base"/>
  </joint>
  <link name="left_index_base_connector">
    <inertial>
      <mass value="0.02"/>
      <inertia ixx="4E-5" ixy="0.0" ixz="0.0" iyy="4E-5" iyz="0.0" izz="4E-5"/>
    </inertial>
    <visual>
      <origin rpy="0 0 0" xyz="0 0 0"/>
      <geometry>
        <mesh filename="package://avatar_gripper_description/meshes/left/index_base_connector.STL"/>
      </geometry>
      <material name="">
        <color rgba="0.9 0.9 0.9 1"/>
      </material>
    </visual>
  </link>
  <link name="left_index_knuckle">
    <inertial>
      <mass value="0.5"/>
      <inertia ixx="4E-5" ixy="0.0" ixz="0.0" iyy="4E-5" iyz="0.0" izz="4E-5"/>
    </inertial>
    <visual>
      <origin rpy="0 0 0" xyz="0 0 0"/>
      <geometry>
        <mesh filename="package://avatar_gripper_description/meshes/left/index_knuckle.STL"/>
      </geometry>
      <material name="">
        <color rgba="0.9 0.9 0.9 1"/>
      </material>
    </visual>
    <collision>
      <origin rpy="0 0 0" xyz="0 0 0"/>
      <geometry>
        <mesh filename="package://avatar_gripper_description/meshes/left/index_knuckle.STL"/>
      </geometry>
    </collision>
  </link>
  <joint name="left_index_knuckle_joint" type="revolute">
    <origin rpy="1.19730672 1.07478656 1.15162329" xyz="+0.021564878 0.008545 -0.0024358"/>
    <parent link="left_index_base_connector"/>
    <child link="left_index_knuckle"/>
    <axis xyz="0 0 1"/>
    <limit effort="1000" lower="-0.8" upper="0" velocity="2.0"/>
  </joint>
  <link name="left_index_fingertip">
    <inertial>
      <mass value="0.5"/>
      <inertia ixx="4E-5" ixy="0.0" ixz="0.0" iyy="4E-5" iyz="0.0" izz="4E-5"/>
    </inertial>
    <visual>
      <origin rpy="0 0 0" xyz="0 0 0"/>
      <geometry>
        <mesh filename="package://avatar_gripper_description/meshes/left/index_fingertip.STL"/>
      </geometry>
      <material name="">
        <color rgba="0.9 0.9 0.9 1"/>
      </material>
    </visual>
    <collision>
      <origin rpy="0 0 0" xyz="0 0 0"/>
      <geometry>
        <mesh filename="package://avatar_gripper_description/meshes/left/index_fingertip.STL"/>
      </geometry>
    </collision>
  </link>
  <joint name="left_index_fingertip_joint" type="revolute">
    <origin rpy="0 0 -0.35" xyz="0.0353829 -0.02780 0"/>
    <parent link="left_index_knuckle"/>
    <child link="left_index_fingertip"/>
    <axis xyz="0 0 1"/>
    <limit effort="1000" lower="-0.8" upper="0" velocity="2.0"/>
  </joint>
  <link name="left_middle_knuckle">
    <inertial>
      <mass value="0.5"/>
      <inertia ixx="4E-5" ixy="0.0" ixz="0.0" iyy="4E-5" iyz="0.0" izz="4E-5"/>
    </inertial>
    <visual>
      <origin rpy="0 0 0" xyz="0 0 0"/>
      <geometry>
        <mesh filename="package://avatar_gripper_description/meshes/left/index_knuckle.STL"/>
      </geometry>
      <material name="">
        <color rgba="0.9 0.9 0.9 1"/>
      </material>
    </visual>
    <collision>
      <origin rpy="0 0 0" xyz="0 0 0"/>
      <geometry>
        <mesh filename="package://avatar_gripper_description/meshes/left/index_knuckle.STL"/>
      </geometry>
    </collision>
  </link>
  <joint name="left_middle_knuckle_joint" type="revolute">
    <origin rpy="1.94428593 1.07478656 1.98996937" xyz="-0.02156 0.008545 -0.0024358"/>
    <parent link="left_index_base_connector"/>
    <child link="left_middle_knuckle"/>
    <axis xyz="0 0 1"/>
    <limit effort="1000" lower="-0.8" upper="0" velocity="2.0"/>
  </joint>
  <link name="left_middle_fingertip">
    <inertial>
      <mass value="0.5"/>
      <inertia ixx="4E-5" ixy="0.0" ixz="0.0" iyy="4E-5" iyz="0.0" izz="4E-5"/>
    </inertial>
    <visual>
      <origin rpy="0 0 0" xyz="0 0 0"/>
      <geometry>
        <mesh filename="package://avatar_gripper_description/meshes/left/index_fingertip.STL"/>
      </geometry>
      <material name="">
        <color rgba="0.9 0.9 0.9 1"/>
      </material>
    </visual>
    <collision>
      <origin rpy="0 0 0" xyz="0 0 0"/>
      <geometry>
        <mesh filename="package://avatar_gripper_description/meshes/left/index_fingertip.STL"/>
      </geometry>
    </collision>
  </link>
  <joint name="left_middle_fingertip_joint" type="revolute">
    <origin rpy="0 0 -0.35" xyz="0.0353829 -0.02780 0"/>
    <parent link="left_middle_knuckle"/>
    <child link="left_middle_fingertip"/>
    <axis xyz="0 0 1"/>
    <limit effort="1000" lower="-0.8" upper="0" velocity="2.0"/>
  </joint>
  <link name="left_gripper_base">
    <inertial>
      <mass value="2.0"/>
      <inertia ixx="7.11E-3" ixy="0.0" ixz="0.0" iyy="7.11E-3" iyz="0.0" izz="7.11E-3"/>
    </inertial>
    <visual>
      <origin rpy="0 0 0" xyz="0 0 0"/>
      <geometry>
        <mesh filename="package://avatar_gripper_description/meshes/left/gripper_base.STL"/>
      </geometry>
      <material name="">
        <color rgba="0.9 0.9 0.7 1"/>
      </material>
    </visual>
    <collision>
      <origin rpy="0 0 0" xyz="0 0 -0.03"/>
      <geometry>
        <box size="0.1 0.1 0.06"/>
      </geometry>
    </collision>
  </link>
  <joint name="left_gripper_base_joint" type="fixed">
    <origin rpy="1.57 0 0" xyz="-0.00736 0.139 -0.066017"/>
    <parent link="left_gripper_base"/>
    <child link="left_index_base_connector"/>
  </joint>
  <link name="left_thumb_flex_motor">
    <inertial>
      <mass value="0.25"/>
      <inertia ixx="1.463E-04" ixy="0" ixz="0" iyy="1.463E-04" iyz="0" izz="1.463E-04"/>
    </inertial>
    <visual>
      <origin rpy="0 0 0" xyz="0 0 0"/>
      <geometry>
        <cylinder length="0.01" radius="0.02"/>
      </geometry>
    </visual>
  </link>
  <joint name="left_thumb_flex_motor_joint" type="revolute">
    <origin rpy="0 0 0" xyz="-0.05 -0.3 0"/>
    <parent link="left_gripper_base"/>
    <child link="left_thumb_flex_motor"/>
    <axis xyz="0 0 1"/>
    <limit effort="1000" lower="-2.3" upper="-0.08" velocity="2.0"/>
  </joint>
  <link name="left_thumb_swivel_motor">
    <inertial>
      <mass value="0.25"/>
      <inertia ixx="1.463E-04" ixy="0" ixz="0" iyy="1.463E-04" iyz="0" izz="1.463E-04"/>
    </inertial>
    <visual>
      <origin rpy="0 0 0" xyz="0 0 0"/>
      <geometry>
        <cylinder length="0.01" radius="0.02"/>
      </geometry>
    </visual>
  </link>
  <joint name="left_thumb_swivel_motor_joint" type="revolute">
    <origin rpy="0 0 0" xyz="-0.1 -0.3 0"/>
    <parent link="left_gripper_base"/>
    <child link="left_thumb_swivel_motor"/>
    <axis xyz="0 0 1"/>
    <limit effort="1000" lower="-2.3" upper="-0.05" velocity="2.0"/>
  </joint>
  <link name="left_index_flex_motor">
    <inertial>
      <mass value="0.25"/>
      <inertia ixx="1.463E-04" ixy="0" ixz="0" iyy="1.463E-04" iyz="0" izz="1.463E-04"/>
    </inertial>
    <visual>
      <origin rpy="0 0 0" xyz="0 0 0"/>
      <geometry>
        <cylinder length="0.01" radius="0.02"/>
      </geometry>
    </visual>
  </link>
  <joint name="left_index_flex_motor_joint" type="revolute">
    <origin rpy="0 0 0" xyz="0 -0.3 0"/>
    <parent link="left_gripper_base"/>
    <child link="left_index_flex_motor"/>
    <axis xyz="0 0 1"/>
    <limit effort="1000" lower="-2.3" upper="-0.08" velocity="2.0"/>
  </joint>
  <joint name="left_panda_gripper_joint" type="fixed">
    <parent link="left_panda_link8"/>
    <child link="left_gripper_base"/>
    <origin rpy="0 3.141592653589793 -0.7853981633974483" xyz="0 0 0"/>
  </joint>
</robot>

